Workbook

Sheet EERR Mensual
A1: CASA ORTIZ | J1: AÑO 1 | X1: AÑO 2 | AL1: AÑO 2
I2: 0 | J2: 1 | K2: 2 | L2: 3 | M2: 4 | N2: 5 | O2: 6 | P2: 7 | Q2: 8 | R2: 9 | S2: 10 | T2: 11 | U2: 12 | X2: 1 | Y2: 2 | Z2: 3 | AA2: 4 | AB2: 5 | AC2: 6 | AD2: 7 | AE2: 8 | AF2: 9 | AG2: 10 | AH2: 11 | AI2: 12 | AL2: 1 | AM2: 2 | AN2: 3 | AO2: 4 | AP2: 5 | AQ2: 6 | AR2: 7 | AS2: 8 | AT2: 9 | AU2: 10 | AV2: 11 | AW2: 12
J3: Ago | K3: Sep | L3: Oct | M3: Nov | N3: Dic | O3: Ene | P3: Feb | Q3: Mar | R3: Abr | S3: May | T3: Jun | U3: Jul | X3: Ago | Y3: Sep | Z3: Oct | AA3: Nov | AB3: Dic | AC3: Ene | AD3: Feb | AE3: Mar | AF3: Abr | AG3: May | AH3: Jun | AI3: Jul | AL3: Ago | AM3: Sep | AN3: Oct | AO3: Nov | AP3: Dic | AQ3: Ene | AR3: Feb | AS3: Mar | AT3: Abr | AU3: May | AV3: Jun | AW3: Jul
B4: Precision Cubiertos | C4: 1 | F4: Estado de Resultados
F5: Ventas | J5: =J6*$C$6 -> 1.4106362e+08 | K5: =K6*$C$6 -> 163970730 | L5: =L6*$C$6 -> 158149530 | M5: =M6*$C$6 -> 2.3407634e+08 | N5: =N6*$C$6 -> 186981795 | O5: =O6*$C$6 -> 1.3191428e+08 | P5: =P6*$C$6 -> 156056670 | Q5: =Q6*$C$6 -> 2.2076381e+08 | ... U5: =U6*$C$6 -> 2.641716e+08 | X5: =X6*$C$6 -> 1.5388758e+08 | Y5: =Y6*$C$6 -> 273284550 | Z5: =Z6*$C$6 -> 2.6358255e+08 | AA5: =AA6*$C$6 -> 3.6011745e+08 | AB5: =AB6*$C$6 -> 287664300 | AC5: =AC6*$C$6 -> 2.0294505e+08 | AD5: =AD6*$C$6 -> 2.229381e+08 | AE5: =AE6*$C$6 -> 294351750 | ... AI5: =AI6*$C$6 -> 2.641716e+08 | AL5: =AL6*$C$6 -> 233163000 | AM5: =AM6*$C$6 -> 248440500 | AN5: =AN6*$C$6 -> 239620500 | AO5: =AO6*$C$6 -> 327379500 | AP5: =AP6*$C$6 -> 261513000 | AQ5: =AQ6*$C$6 -> 184495500 | AR5: =AR6*$C$6 -> 202671000 | AS5: =AS6*$C$6 -> 267592500 | ... AW5: =AW6*$C$6 -> 240156000
B6: Ticket Promedio | C6: 31500 | G6: Cubiertos | J6: =(J8*J7)*$C$4 -> 4478.21 | K6: =(K8*K7)*$C$4 -> 5205.42 | L6: =(L8*L7)*$C$4 -> 5020.62 | M6: =(M8*M7)*$C$4 -> 7430.995 | N6: =(N8*N7)*$C$4 -> 5935.93 | O6: =(O8*O7)*$C$4 -> 4187.755 | P6: =(P8*P7)*$C$4 -> 4954.18 | Q6: =(Q8*Q7)*$C$4 -> 7008.375 | ... U6: =(U8*U7)*$C$4 -> 8386.4 | X6: =(X8*X7)*$C$4 -> 4885.32 | Y6: =(Y8*Y7)*$C$4 -> 8675.7 | Z6: =(Z8*Z7)*$C$4 -> 8367.7 | AA6: =(AA8*AA7)*$C$4 -> 11432.3 | AB6: =(AB8*AB7)*$C$4 -> 9132.2 | AC6: =(AC8*AC7)*$C$4 -> 6442.7 | AD6: =(AD8*AD7)*$C$4 -> 7077.4 | AE6: =(AE8*AE7)*$C$4 -> 9344.5 | ... AI6: =(AI8*AI7)*$C$4 -> 8386.4 | AL6: =(AL8*AL7)*$C$4 -> 7402 | AM6: =(AM8*AM7)*$C$4 -> 7887 | AN6: =(AN8*AN7)*$C$4 -> 7607 | AO6: =(AO8*AO7)*$C$4 -> 10393 | AP6: =(AP8*AP7)*$C$4 -> 8302 | AQ6: =(AQ8*AQ7)*$C$4 -> 5857 | AR6: =(AR8*AR7)*$C$4 -> 6434 | AS6: =(AS8*AS7)*$C$4 -> 8495 | ... AW6: =(AW8*AW7)*$C$4 -> 7624
G7: Ramp - up | J7: 0.55 | K7: 0.6 | L7: 0.6 | M7: 0.65 | N7: 0.65 | O7: 0.65 | P7: 0.7 | Q7: 0.75 | R7: 0.8 | S7: 0.85 | T7: 0.9 | U7: 1 | X7: 0.6 | Y7: 1 | Z7: 1 | AA7: 1 | AB7: 1 | AC7: 1 | AD7: 1 | AE7: 1 | AF7: 1 | AG7: 1 | AH7: 1 | AI7: 1 | AL7: 1 | AM7: 1 | AN7: 1 | AO7: 1 | AP7: 1 | AQ7: 1 | AR7: 1 | AS7: 1 | AT7: 1 | AU7: 1 | AV7: 1 | AW7: 1
B8: Porcentaje CMV | C8: 0.34 | G8: Proyeccion Ventas | J8: 8142.2 | K8: 8675.7 | L8: 8367.7 | M8: 11432.3 | N8: 9132.2 | O8: 6442.7 | P8: 7077.4 | Q8: 9344.5 | R8: 9356.6 | S8: 8954 | T8: 6920.1 | U8: 8386.4 | X8: 8142.2 | Y8: 8675.7 | Z8: 8367.7 | AA8: 11432.3 | AB8: 9132.2 | AC8: 6442.7 | AD8: 7077.4 | AE8: 9344.5 | AF8: 9356.6 | AG8: 8954 | AH8: 6920.1 | AI8: 8386.4 | AL8: 7402 | AM8: 7887 | AN8: 7607 | AO8: 10393 | AP8: 8302 | AQ8: 5857 | AR8: 6434 | AS8: 8495 | AT8: 8506 | AU8: 8140 | AV8: 6291 | AW8: 7624
X9: =+X8*1.03 -> 8386.466 | Y9: =+Y8*1.05 -> 9109.485 | Z9: =+Z8*1.05 -> 8786.085 | AA9: =+AA8*1.05 -> 12003.915 | AB9: =+AB8*1.05 -> 9588.81 | AC9: =+AC8*1.05 -> 6764.835 | AD9: =+AD8*1.05 -> 7431.27 | AE9: =+AE8*1.05 -> 9811.725 | AF9: =+AF8*1.05 -> 9824.43 | ... AI9: =+AI8*1.05 -> 8805.72
B10: Costo Delivery | C10: 0.015 | F10: Costos Variables | J10: =SUM(J11:J18) -> 69121171 | K10: =SUM(K11:K18) -> 80345658 | L10: =SUM(L11:L18) -> 77493270 | M10: =SUM(M11:M18) -> 1.1469741e+08 | N10: =SUM(N11:N18) -> 91621080 | O10: =SUM(O11:O18) -> 64637998 | P10: =SUM(P11:P18) -> 76467768 | Q10: =SUM(Q11:Q18) -> 1.0817427e+08 | ... U10: =SUM(U11:U18) -> 1.2944408e+08 | X10: =SUM(X11:X18) -> 75404914 | Y10: =SUM(Y11:Y18) -> 1.3390943e+08 | Z10: =SUM(Z11:Z18) -> 1.2915545e+08 | AA10: =SUM(AA11:AA18) -> 1.7645755e+08 | AB10: =SUM(AB11:AB18) -> 140955507 | AC10: =SUM(AC11:AC18) -> 99443075 | AD10: =SUM(AD11:AD18) -> 1.0923967e+08 | AE10: =SUM(AE11:AE18) -> 1.4423236e+08 | ... AI10: =SUM(AI11:AI18) -> 1.2944408e+08 | AL10: =SUM(AL11:AL18) -> 114249870 | AM10: =SUM(AM11:AM18) -> 121735845 | AN10: =SUM(AN11:AN18) -> 117414045 | AO10: =SUM(AO11:AO18) -> 160415955 | AP10: =SUM(AP11:AP18) -> 128141370 | AQ10: =SUM(AQ11:AQ18) -> 90402795 | AR10: =SUM(AR11:AR18) -> 99308790 | AS10: =SUM(AS11:AS18) -> 131120325 | ... AW10: =SUM(AW11:AW18) -> 117676440
F11: Proveedores | G11: Costo de mercadería | J11: =J5*$C$8 -> 47961629 | K11: =K5*$C$8 -> 55750048 | L11: =L5*$C$8 -> 53770840 | M11: =M5*$C$8 -> 79585956 | N11: =N5*$C$8 -> 63573810 | O11: =O5*$C$8 -> 44850856 | P11: =P5*$C$8 -> 53059268 | Q11: =Q5*$C$8 -> 75059696 | ... U11: =U5*$C$8 -> 89818344 | X11: =X5*$C$8 -> 52321777 | Y11: =Y5*$C$8 -> 92916747 | Z11: =Z5*$C$8 -> 89618067 | AA11: =AA5*$C$8 -> 1.2243993e+08 | AB11: =AB5*$C$8 -> 97805862 | AC11: =AC5*$C$8 -> 69001317 | AD11: =AD5*$C$8 -> 75798954 | AE11: =AE5*$C$8 -> 100079595 | ... AI11: =AI5*$C$8 -> 89818344 | AL11: =AL5*$C$8 -> 79275420 | AM11: =AM5*$C$8 -> 84469770 | AN11: =AN5*$C$8 -> 81470970 | AO11: =AO5*$C$8 -> 1.1130903e+08 | AP11: =AP5*$C$8 -> 88914420 | AQ11: =AQ5*$C$8 -> 62728470 | AR11: =AR5*$C$8 -> 68908140 | AS11: =AS5*$C$8 -> 90981450 | ... AW11: =AW5*$C$8 -> 81653040
B12: Gastos Adición | C12: 0.0025 | F12: Proveedores | G12: Costo delivery | J12: =J5*$C$10 -> 2115954.2 | K12: =K5*$C$10 -> 2459560.9 | L12: =L5*$C$10 -> 2372242.9 | M12: =M5*$C$10 -> 3511145.1 | N12: =N5*$C$10 -> 2804726.9 | O12: =O5*$C$10 -> 1978714.2 | P12: =P5*$C$10 -> 2340850 | Q12: =Q5*$C$10 -> 3311457.2 | ... U12: =U5*$C$10 -> 3962574 | X12: =X5*$C$10 -> 2308313.7 | Y12: =Y5*$C$10 -> 4099268.2 | Z12: =Z5*$C$10 -> 3953738.3 | AA12: =AA5*$C$10 -> 5401761.8 | AB12: =AB5*$C$10 -> 4314964.5 | AC12: =AC5*$C$10 -> 3044175.8 | AD12: =AD5*$C$10 -> 3344071.5 | AE12: =AE5*$C$10 -> 4415276.2 | ... AI12: =AI5*$C$10 -> 3962574 | AL12: =AL5*$C$10 -> 3497445 | AM12: =AM5*$C$10 -> 3726607.5 | AN12: =AN5*$C$10 -> 3594307.5 | AO12: =AO5*$C$10 -> 4910692.5 | AP12: =AP5*$C$10 -> 3922695 | AQ12: =AQ5*$C$10 -> 2767432.5 | AR12: =AR5*$C$10 -> 3040065 | AS12: =AS5*$C$10 -> 4013887.5 | ... AW12: =AW5*$C$10 -> 3602340
F13: Proveedores | G13: Gastos adición | J13: =J5*$C$12 -> 352659.04 | K13: =K5*$C$12 -> 409926.83 | L13: =L5*$C$12 -> 395373.83 | M13: =M5*$C$12 -> 585190.86 | N13: =N5*$C$12 -> 467454.49 | O13: =O5*$C$12 -> 329785.71 | P13: =P5*$C$12 -> 390141.67 | Q13: =Q5*$C$12 -> 551909.53 | ... U13: =U5*$C$12 -> 660429 | X13: =X5*$C$12 -> 384718.95 | Y13: =Y5*$C$12 -> 683211.38 | Z13: =Z5*$C$12 -> 658956.38 | AA13: =AA5*$C$12 -> 900293.63 | AB13: =AB5*$C$12 -> 719160.75 | AC13: =AC5*$C$12 -> 507362.63 | AD13: =AD5*$C$12 -> 557345.25 | AE13: =AE5*$C$12 -> 735879.38 | ... AI13: =AI5*$C$12 -> 660429 | AL13: =AL5*$C$12 -> 582907.5 | AM13: =AM5*$C$12 -> 621101.25 | AN13: =AN5*$C$12 -> 599051.25 | AO13: =AO5*$C$12 -> 818448.75 | AP13: =AP5*$C$12 -> 653782.5 | AQ13: =AQ5*$C$12 -> 461238.75 | AR13: =AR5*$C$12 -> 506677.5 | AS13: =AS5*$C$12 -> 668981.25 | ... AW13: =AW5*$C$12 -> 600390
B14: Com. / Impuestos | C14: 0.11 | G14: Com. / Impuestos (Incluye Iva) | J14: =J5*$C$14 -> 15516998 | K14: =K5*$C$14 -> 18036780 | L14: =L5*$C$14 -> 17396448 | M14: =M5*$C$14 -> 25748398 | N14: =N5*$C$14 -> 20567997 | O14: =O5*$C$14 -> 14510571 | P14: =P5*$C$14 -> 17166234 | Q14: =Q5*$C$14 -> 24284019 | ... U14: =U5*$C$14 -> 29058876 | X14: =X5*$C$14 -> 16927634 | Y14: =Y5*$C$14 -> 30061300 | Z14: =Z5*$C$14 -> 28994081 | AA14: =AA5*$C$14 -> 39612920 | AB14: =AB5*$C$14 -> 31643073 | AC14: =AC5*$C$14 -> 22323956 | AD14: =AD5*$C$14 -> 24523191 | AE14: =AE5*$C$14 -> 32378692 | ... AI14: =AI5*$C$14 -> 29058876 | AL14: =AL5*$C$14 -> 25647930 | AM14: =AM5*$C$14 -> 27328455 | AN14: =AN5*$C$14 -> 26358255 | AO14: =AO5*$C$14 -> 36011745 | AP14: =AP5*$C$14 -> 28766430 | AQ14: =AQ5*$C$14 -> 20294505 | AR14: =AR5*$C$14 -> 22293810 | AS14: =AS5*$C$14 -> 29435175 | ... AW14: =AW5*$C$14 -> 26417160
F15: Proveedores | G15: Mantenimiento | J15: =J5*$C$20 -> 1410636.2 | K15: =K5*$C$20 -> 1639707.3 | L15: =L5*$C$20 -> 1581495.3 | M15: =M5*$C$20 -> 2340763.4 | N15: =N5*$C$20 -> 1869817.9 | O15: =O5*$C$20 -> 1319142.8 | P15: =P5*$C$20 -> 1560566.7 | Q15: =Q5*$C$20 -> 2207638.1 | ... U15: =U5*$C$20 -> 2641716 | X15: =X5*$C$20 -> 1538875.8 | Y15: =Y5*$C$20 -> 2732845.5 | Z15: =Z5*$C$20 -> 2635825.5 | AA15: =AA5*$C$20 -> 3601174.5 | AB15: =AB5*$C$20 -> 2876643 | AC15: =AC5*$C$20 -> 2029450.5 | AD15: =AD5*$C$20 -> 2229381 | AE15: =AE5*$C$20 -> 2943517.5 | ... AI15: =AI5*$C$20 -> 2641716 | AL15: =AL5*$C$20 -> 2331630 | AM15: =AM5*$C$20 -> 2484405 | AN15: =AN5*$C$20 -> 2396205 | AO15: =AO5*$C$20 -> 3273795 | AP15: =AP5*$C$20 -> 2615130 | AQ15: =AQ5*$C$20 -> 1844955 | AR15: =AR5*$C$20 -> 2026710 | AS15: =AS5*$C$20 -> 2675925 | ... AW15: =AW5*$C$20 -> 2401560
B16: Marketing | C16: 2000000 | F16: Proveedores | G16: Bazar | J16: =J5*$C$26 -> 352659.04 | K16: =K5*$C$26 -> 409926.83 | L16: =L5*$C$26 -> 395373.83 | M16: =M5*$C$26 -> 585190.86 | N16: =N5*$C$26 -> 467454.49 | O16: =O5*$C$26 -> 329785.71 | P16: =P5*$C$26 -> 390141.67 | Q16: =Q5*$C$26 -> 551909.53 | ... U16: =U5*$C$26 -> 660429 | X16: =X5*$C$26 -> 384718.95 | Y16: =Y5*$C$26 -> 683211.38 | Z16: =Z5*$C$26 -> 658956.38 | AA16: =AA5*$C$26 -> 900293.63 | AB16: =AB5*$C$26 -> 719160.75 | AC16: =AC5*$C$26 -> 507362.63 | AD16: =AD5*$C$26 -> 557345.25 | AE16: =AE5*$C$26 -> 735879.38 | ... AI16: =AI5*$C$26 -> 660429 | AL16: =AL5*$C$26 -> 582907.5 | AM16: =AM5*$C$26 -> 621101.25 | AN16: =AN5*$C$26 -> 599051.25 | AO16: =AO5*$C$26 -> 818448.75 | AP16: =AP5*$C$26 -> 653782.5 | AQ16: =AQ5*$C$26 -> 461238.75 | AR16: =AR5*$C$26 -> 506677.5 | AS16: =AS5*$C$26 -> 668981.25 | ... AW16: =AW5*$C$26 -> 600390
F17: Proveedores | G17: Inversión | J17: =J5*$C$28 -> 1410636.2 | K17: =K5*$C$28 -> 1639707.3 | L17: =L5*$C$28 -> 1581495.3 | M17: =M5*$C$28 -> 2340763.4 | N17: =N5*$C$28 -> 1869817.9 | O17: =O5*$C$28 -> 1319142.8 | P17: =P5*$C$28 -> 1560566.7 | Q17: =Q5*$C$28 -> 2207638.1 | ... U17: =U5*$C$28 -> 2641716 | X17: =X5*$C$28 -> 1538875.8 | Y17: =Y5*$C$28 -> 2732845.5 | Z17: =Z5*$C$28 -> 2635825.5 | AA17: =AA5*$C$28 -> 3601174.5 | AB17: =AB5*$C$28 -> 2876643 | AC17: =AC5*$C$28 -> 2029450.5 | AD17: =AD5*$C$28 -> 2229381 | AE17: =AE5*$C$28 -> 2943517.5 | ... AI17: =AI5*$C$28 -> 2641716 | AL17: =AL5*$C$28 -> 2331630 | AM17: =AM5*$C$28 -> 2484405 | AN17: =AN5*$C$28 -> 2396205 | AO17: =AO5*$C$28 -> 3273795 | AP17: =AP5*$C$28 -> 2615130 | AQ17: =AQ5*$C$28 -> 1844955 | AR17: =AR5*$C$28 -> 2026710 | AS17: =AS5*$C$28 -> 2675925 | ... AW17: =AW5*$C$28 -> 2401560
B18: Nomina Full | C18: 60000000
F19: Márgen Bruto | H19: ARS | J19: =J5-J10 -> 71942444 | K19: =K5-K10 -> 83625072 | L19: =L5-L10 -> 80656260 | M19: =M5-M10 -> 1.1937893e+08 | N19: =N5-N10 -> 95360715 | O19: =O5-O10 -> 67276284 | P19: =P5-P10 -> 79588902 | Q19: =Q5-Q10 -> 1.1258954e+08 | ... U19: =U5-U10 -> 1.3472752e+08 | W19: ARS | X19: =X5-X10 -> 78482666 | Y19: =Y5-Y10 -> 1.3937512e+08 | Z19: =Z5-Z10 -> 1.344271e+08 | AA19: =AA5-AA10 -> 1.836599e+08 | AB19: =AB5-AB10 -> 146708793 | AC19: =AC5-AC10 -> 1.0350198e+08 | AD19: =AD5-AD10 -> 1.1369843e+08 | AE19: =AE5-AE10 -> 1.5011939e+08 | ... AI19: =AI5-AI10 -> 1.3472752e+08 | AK19: ARS | AL19: =AL5-AL10 -> 118913130 | AM19: =AM5-AM10 -> 126704655 | AN19: =AN5-AN10 -> 122206455 | AO19: =AO5-AO10 -> 166963545 | AP19: =AP5-AP10 -> 133371630 | AQ19: =AQ5-AQ10 -> 94092705 | AR19: =AR5-AR10 -> 103362210 | AS19: =AS5-AS10 -> 136472175 | ... AW19: =AW5-AW10 -> 122479560
B20: Mantenimiento | C20: 0.01 | H20: % | J20: =J19/J5 -> 0.51 | K20: =K19/K5 -> 0.51 | L20: =L19/L5 -> 0.51 | M20: =M19/M5 -> 0.51 | N20: =N19/N5 -> 0.51 | O20: =O19/O5 -> 0.51 | P20: =P19/P5 -> 0.51 | Q20: =Q19/Q5 -> 0.51 | ... U20: =U19/U5 -> 0.51 | W20: % | X20: =X19/X5 -> 0.51 | Y20: =Y19/Y5 -> 0.51 | Z20: =Z19/Z5 -> 0.51 | AA20: =AA19/AA5 -> 0.51 | AB20: =AB19/AB5 -> 0.51 | AC20: =AC19/AC5 -> 0.51 | AD20: =AD19/AD5 -> 0.51 | AE20: =AE19/AE5 -> 0.51 | ... AI20: =AI19/AI5 -> 0.51 | AK20: % | AL20: =AL19/AL5 -> 0.51 | AM20: =AM19/AM5 -> 0.51 | AN20: =AN19/AN5 -> 0.51 | AO20: =AO19/AO5 -> 0.51 | AP20: =AP19/AP5 -> 0.51 | AQ20: =AQ19/AQ5 -> 0.51 | AR20: =AR19/AR5 -> 0.51 | AS20: =AS19/AS5 -> 0.51 | ... AW20: =AW19/AW5 -> 0.51
B22: Gastos Operativos | C22: 3000000 | G22: Ramp - up Nómina | J22: 0.67 | K22: 0.67 | L22: 0.67 | M22: 0.75 | N22: 0.75 | O22: 0.67 | P22: 0.67 | Q22: 0.75 | R22: 0.75 | S22: 0.75 | T22: 0.75 | U22: 0.9 | X22: 1 | Y22: 1 | Z22: 1 | AA22: 1 | AB22: 1 | AC22: 1 | AD22: 1 | AE22: 1 | AF22: 1 | AG22: 1 | AH22: 1 | AI22: 1 | AL22: 1 | AM22: 1 | AN22: 1 | AO22: 1 | AP22: 1 | AQ22: 1 | AR22: 1 | AS22: 1 | AT22: 1 | AU22: 1 | AV22: 1 | AW22: 1
F23: Costos Estructura | J23: =SUM(J24:J33) -> 79036000 | K23: =SUM(K24:K33) -> 79036000 | L23: =SUM(L24:L33) -> 79036000 | M23: =SUM(M24:M33) -> 84236000 | N23: =SUM(N24:N33) -> 84236000 | O23: =SUM(O24:O33) -> 79036000 | P23: =SUM(P24:P33) -> 79036000 | Q23: =SUM(Q24:Q33) -> 84236000 | ... U23: =SUM(U24:U33) -> 93986000 | X23: =SUM(X24:X33) -> 100486000 | Y23: =SUM(Y24:Y33) -> 100486000 | Z23: =SUM(Z24:Z33) -> 100486000 | AA23: =SUM(AA24:AA33) -> 100486000 | AB23: =SUM(AB24:AB33) -> 100486000 | AC23: =SUM(AC24:AC33) -> 100486000 | AD23: =SUM(AD24:AD33) -> 100486000 | AE23: =SUM(AE24:AE33) -> 100486000 | ... AI23: =SUM(AI24:AI33) -> 100486000 | AL23: =SUM(AL24:AL33) -> 100486000 | AM23: =SUM(AM24:AM33) -> 100486000 | AN23: =SUM(AN24:AN33) -> 100486000 | AO23: =SUM(AO24:AO33) -> 100486000 | AP23: =SUM(AP24:AP33) -> 100486000 | AQ23: =SUM(AQ24:AQ33) -> 100486000 | AR23: =SUM(AR24:AR33) -> 100486000 | AS23: =SUM(AS24:AS33) -> 100486000 | ... AW23: =SUM(AW24:AW33) -> 100486000
B24: Honorarios | C24: 2300000 | F24: Proveedores | G24: RRHH | J24: =$C$18*J22 -> 40200000 | K24: =$C$18*K22 -> 40200000 | L24: =$C$18*L22 -> 40200000 | M24: =$C$18*M22 -> 45000000 | N24: =$C$18*N22 -> 45000000 | O24: =$C$18*O22 -> 40200000 | P24: =$C$18*P22 -> 40200000 | Q24: =$C$18*Q22 -> 45000000 | ... U24: =$C$18*U22 -> 54000000 | X24: =$C$18*X22 -> 60000000 | Y24: =$C$18*Y22 -> 60000000 | Z24: =$C$18*Z22 -> 60000000 | AA24: =$C$18*AA22 -> 60000000 | AB24: =$C$18*AB22 -> 60000000 | AC24: =$C$18*AC22 -> 60000000 | AD24: =$C$18*AD22 -> 60000000 | AE24: =$C$18*AE22 -> 60000000 | ... AI24: =$C$18*AI22 -> 60000000 | AL24: =$C$18*AL22 -> 60000000 | AM24: =$C$18*AM22 -> 60000000 | AN24: =$C$18*AN22 -> 60000000 | AO24: =$C$18*AO22 -> 60000000 | AP24: =$C$18*AP22 -> 60000000 | AQ24: =$C$18*AQ22 -> 60000000 | AR24: =$C$18*AR22 -> 60000000 | AS24: =$C$18*AS22 -> 60000000 | ... AW24: =$C$18*AW22 -> 60000000
F25: Proveedores | G25: Costo Locativo | J25: 12500000 | K25: 12500000 | L25: 12500000 | M25: 12500000 | N25: 12500000 | O25: 12500000 | P25: 12500000 | Q25: 12500000 | R25: 12500000 | S25: 12500000 | T25: 12500000 | U25: 12500000 | X25: 12500000 | Y25: 12500000 | Z25: 12500000 | AA25: 12500000 | AB25: 12500000 | AC25: 12500000 | AD25: 12500000 | AE25: 12500000 | AF25: 12500000 | AG25: 12500000 | AH25: 12500000 | AI25: 12500000 | AL25: 12500000 | AM25: 12500000 | AN25: 12500000 | AO25: 12500000 | AP25: 12500000 | AQ25: 12500000 | AR25: 12500000 | AS25: 12500000 | AT25: 12500000 | AU25: 12500000 | AV25: 12500000 | AW25: 12500000
B26: Bazar | C26: 0.0025 | F26: Proveedores | G26: Servicios públicos | J26: 6800000 | K26: 6800000 | L26: 6800000 | M26: 6800000 | N26: 6800000 | O26: 6800000 | P26: 6800000 | Q26: 6800000 | R26: 6800000 | S26: 6800000 | T26: 6800000 | U26: 6800000 | X26: 6800000 | Y26: 6800000 | Z26: 6800000 | AA26: 6800000 | AB26: 6800000 | AC26: 6800000 | AD26: 6800000 | AE26: 6800000 | AF26: 6800000 | AG26: 6800000 | AH26: 6800000 | AI26: 6800000 | AL26: 6800000 | AM26: 6800000 | AN26: 6800000 | AO26: 6800000 | AP26: 6800000 | AQ26: 6800000 | AR26: 6800000 | AS26: 6800000 | AT26: 6800000 | AU26: 6800000 | AV26: 6800000 | AW26: 6800000
F27: Proveedores | G27: Marketing | J27: =$C$16 -> 2000000 | K27: =$C$16 -> 2000000 | L27: =$C$16 -> 2000000 | M27: =$C$16 -> 2000000 | N27: =$C$16 -> 2000000 | O27: =$C$16 -> 2000000 | P27: =$C$16 -> 2000000 | Q27: =$C$16 -> 2000000 | ... U27: =$C$16 -> 2000000 | X27: =$C$16 -> 2000000 | Y27: =$C$16 -> 2000000 | Z27: =$C$16 -> 2000000 | AA27: =$C$16 -> 2000000 | AB27: =$C$16 -> 2000000 | AC27: =$C$16 -> 2000000 | AD27: =$C$16 -> 2000000 | AE27: =$C$16 -> 2000000 | ... AI27: =$C$16 -> 2000000 | AL27: =$C$16 -> 2000000 | AM27: =$C$16 -> 2000000 | AN27: =$C$16 -> 2000000 | AO27: =$C$16 -> 2000000 | AP27: =$C$16 -> 2000000 | AQ27: =$C$16 -> 2000000 | AR27: =$C$16 -> 2000000 | AS27: =$C$16 -> 2000000 | ... AW27: =$C$16 -> 2000000
B28: Inversión | C28: 0.01 | F28: Proveedores | G28: Gastos Operativos | J28: =$C$22 -> 3000000 | K28: =$C$22 -> 3000000 | L28: =$C$22 -> 3000000 | M28: =$C$22 -> 3000000 | N28: =$C$22 -> 3000000 | O28: =$C$22 -> 3000000 | P28: =$C$22 -> 3000000 | Q28: =$C$22 -> 3000000 | ... U28: =$C$22 -> 3000000 | X28: =$C$22 -> 3000000 | Y28: =$C$22 -> 3000000 | Z28: =$C$22 -> 3000000 | AA28: =$C$22 -> 3000000 | AB28: =$C$22 -> 3000000 | AC28: =$C$22 -> 3000000 | AD28: =$C$22 -> 3000000 | AE28: =$C$22 -> 3000000 | ... AI28: =$C$22 -> 3000000 | AL28: =$C$22 -> 3000000 | AM28: =$C$22 -> 3000000 | AN28: =$C$22 -> 3000000 | AO28: =$C$22 -> 3000000 | AP28: =$C$22 -> 3000000 | AQ28: =$C$22 -> 3000000 | AR28: =$C$22 -> 3000000 | AS28: =$C$22 -> 3000000 | ... AW28: =$C$22 -> 3000000
F29: Proveedores | G29: Honorarios | J29: =$C$24 -> 2300000 | K29: =$C$24 -> 2300000 | L29: =$C$24 -> 2300000 | M29: =$C$24 -> 2300000 | N29: =$C$24 -> 2300000 | O29: =$C$24 -> 2300000 | P29: =$C$24 -> 2300000 | Q29: =$C$24 -> 2300000 | ... U29: =$C$24 -> 2300000 | X29: =$C$24 -> 2300000 | Y29: =$C$24 -> 2300000 | Z29: =$C$24 -> 2300000 | AA29: =$C$24 -> 2300000 | AB29: =$C$24 -> 2300000 | AC29: =$C$24 -> 2300000 | AD29: =$C$24 -> 2300000 | AE29: =$C$24 -> 2300000 | ... AI29: =$C$24 -> 2300000 | AL29: =$C$24 -> 2300000 | AM29: =$C$24 -> 2300000 | AN29: =$C$24 -> 2300000 | AO29: =$C$24 -> 2300000 | AP29: =$C$24 -> 2300000 | AQ29: =$C$24 -> 2300000 | AR29: =$C$24 -> 2300000 | AS29: =$C$24 -> 2300000 | ... AW29: =$C$24 -> 2300000
B30: IIGG | C30: 0.05 | G30: Previsión aguinaldo | J30: =J24/12 -> 3350000 | K30: =K24/12 -> 3350000 | L30: =L24/12 -> 3350000 | M30: =M24/12 -> 3750000 | N30: =N24/12 -> 3750000 | O30: =O24/12 -> 3350000 | P30: =P24/12 -> 3350000 | Q30: =Q24/12 -> 3750000 | ... U30: =U24/12 -> 4500000 | X30: =X24/12 -> 5000000 | Y30: =Y24/12 -> 5000000 | Z30: =Z24/12 -> 5000000 | AA30: =AA24/12 -> 5000000 | AB30: =AB24/12 -> 5000000 | AC30: =AC24/12 -> 5000000 | AD30: =AD24/12 -> 5000000 | AE30: =AE24/12 -> 5000000 | ... AI30: =AI24/12 -> 5000000 | AL30: =AL24/12 -> 5000000 | AM30: =AM24/12 -> 5000000 | AN30: =AN24/12 -> 5000000 | AO30: =AO24/12 -> 5000000 | AP30: =AP24/12 -> 5000000 | AQ30: =AQ24/12 -> 5000000 | AR30: =AR24/12 -> 5000000 | AS30: =AS24/12 -> 5000000 | ... AW30: =AW24/12 -> 5000000
F31: Proveedores | G31: Dirección Operativa | J31: 5000000 | K31: 5000000 | L31: 5000000 | M31: 5000000 | N31: 5000000 | O31: 5000000 | P31: 5000000 | Q31: 5000000 | R31: 5000000 | S31: 5000000 | T31: 5000000 | U31: 5000000 | X31: 5000000 | Y31: 5000000 | Z31: 5000000 | AA31: 5000000 | AB31: 5000000 | AC31: 5000000 | AD31: 5000000 | AE31: 5000000 | AF31: 5000000 | AG31: 5000000 | AH31: 5000000 | AI31: 5000000 | AL31: 5000000 | AM31: 5000000 | AN31: 5000000 | AO31: 5000000 | AP31: 5000000 | AQ31: 5000000 | AR31: 5000000 | AS31: 5000000 | AT31: 5000000 | AU31: 5000000 | AV31: 5000000 | AW31: 5000000
B32: Fondo Despidos | C32: 0.01 | F32: Proveedores | G32: Bruno Bonnao | J32: 3886000 | K32: 3886000 | L32: 3886000 | M32: 3886000 | N32: 3886000 | O32: 3886000 | P32: 3886000 | Q32: 3886000 | R32: 3886000 | S32: 3886000 | T32: 3886000 | U32: 3886000 | X32: 3886000 | Y32: 3886000 | Z32: 3886000 | AA32: 3886000 | AB32: 3886000 | AC32: 3886000 | AD32: 3886000 | AE32: 3886000 | AF32: 3886000 | AG32: 3886000 | AH32: 3886000 | AI32: 3886000 | AL32: 3886000 | AM32: 3886000 | AN32: 3886000 | AO32: 3886000 | AP32: 3886000 | AQ32: 3886000 | AR32: 3886000 | AS32: 3886000 | AT32: 3886000 | AU32: 3886000 | AV32: 3886000 | AW32: 3886000
B34: TIR | C34: ='Cash Flow'!C16 -> 0.36776345 | F34: EBITDA | H34: ARS | J34: =J19-J23 -> -7093556.3 | K34: =K19-K23 -> 4589072.3 | L34: =L19-L23 -> 1620260.3 | M34: =M19-M23 -> 35142935 | N34: =N19-N23 -> 11124715 | O34: =O19-O23 -> -11759716 | P34: =P19-P23 -> 552901.7 | Q34: =Q19-Q23 -> 28353544 | ... U34: =U19-U23 -> 40741516 | W34: ARS | X34: =X19-X23 -> -22003334 | Y34: =Y19-Y23 -> 38889120 | Z34: =Z19-Z23 -> 33941100 | AA34: =AA19-AA23 -> 83173900 | AB34: =AB19-AB23 -> 46222793 | AC34: =AC19-AC23 -> 3015975.5 | AD34: =AD19-AD23 -> 13212431 | AE34: =AE19-AE23 -> 49633392 | ... AI34: =AI19-AI23 -> 34241516 | AK34: ARS | AL34: =AL19-AL23 -> 18427130 | AM34: =AM19-AM23 -> 26218655 | AN34: =AN19-AN23 -> 21720455 | AO34: =AO19-AO23 -> 66477545 | AP34: =AP19-AP23 -> 32885630 | AQ34: =AQ19-AQ23 -> -6393295 | AR34: =AR19-AR23 -> 2876210 | AS34: =AS19-AS23 -> 35986175 | ... AW34: =AW19-AW23 -> 21993560
B35: VAN | C35: ='Cash Flow'!C14 -> 399459.45 | H35: % | J35: =J34/J5 -> -0.050286223 | K35: =K34/K5 -> 0.027987143 | L35: =L34/L5 -> 0.010245116 | M35: =M34/M5 -> 0.1501345 | N35: =N34/N5 -> 0.059496249 | O35: =O34/O5 -> -0.089146647 | P35: =P34/P5 -> 0.0035429546 | Q35: =Q34/Q5 -> 0.12843384 | ... U35: =U34/U5 -> 0.15422368 | W35: % | X35: =X34/X5 -> -0.14298317 | Y35: =Y34/Y5 -> 0.14230267 | Z35: =Z34/Z5 -> 0.12876839 | AA35: =AA34/AA5 -> 0.23096326 | AB35: =AB34/AB5 -> 0.16068311 | AC35: =AC34/AC5 -> 0.014861045 | AD35: =AD34/AD5 -> 0.05926502 | AE35: =AE34/AE5 -> 0.16861932 | ... AI35: =AI34/AI5 -> 0.12961846 | AK35: % | AL35: =AL34/AL5 -> 0.079031107 | AM35: =AM34/AM5 -> 0.10553293 | AN35: =AN34/AN5 -> 0.090645229 | AO35: =AO34/AO5 -> 0.20305958 | AP35: =AP34/AP5 -> 0.12575142 | AQ35: =AQ34/AQ5 -> -0.034652851 | AR35: =AR34/AR5 -> 0.014191522 | AS35: =AS34/AS5 -> 0.13448125 | ... AW35: =AW34/AW5 -> 0.091580306
B37: CAPEX | C37: =-I69 -> 370000 | G37: Depreciaciones | J37: 0 | K37: 0 | L37: 0 | M37: 0 | N37: 0 | O37: 0 | P37: 0 | Q37: 0 | R37: 0 | S37: 0 | T37: 0 | U37: 0 | X37: 0 | Y37: 0 | Z37: 0 | AA37: 0 | AB37: 0 | AC37: 0 | AD37: 0 | AE37: 0 | AF37: 0 | AG37: 0 | AH37: 0 | AI37: 0 | AL37: 0 | AM37: 0 | AN37: 0 | AO37: 0 | AP37: 0 | AQ37: 0 | AR37: 0 | AS37: 0 | AT37: 0 | AU37: 0 | AV37: 0 | AW37: 0
B38: CAJA Operativa | C38: =I66 -> 61000
B39: INV. Requerida | C39: =SUM(C37:C38) -> 431000 | F39: EBIT | H39: ARS | J39: =J34-J37 -> -7093556.3 | K39: =K34-K37 -> 4589072.3 | L39: =L34-L37 -> 1620260.3 | M39: =M34-M37 -> 35142935 | N39: =N34-N37 -> 11124715 | O39: =O34-O37 -> -11759716 | P39: =P34-P37 -> 552901.7 | Q39: =Q34-Q37 -> 28353544 | ... U39: =U34-U37 -> 40741516 | W39: ARS | X39: =X34-X37 -> -22003334 | Y39: =Y34-Y37 -> 38889120 | Z39: =Z34-Z37 -> 33941100 | AA39: =AA34-AA37 -> 83173900 | AB39: =AB34-AB37 -> 46222793 | AC39: =AC34-AC37 -> 3015975.5 | AD39: =AD34-AD37 -> 13212431 | AE39: =AE34-AE37 -> 49633392 | ... AI39: =AI34-AI37 -> 34241516 | AK39: ARS | AL39: =AL34-AL37 -> 18427130 | AM39: =AM34-AM37 -> 26218655 | AN39: =AN34-AN37 -> 21720455 | AO39: =AO34-AO37 -> 66477545 | AP39: =AP34-AP37 -> 32885630 | AQ39: =AQ34-AQ37 -> -6393295 | AR39: =AR34-AR37 -> 2876210 | AS39: =AS34-AS37 -> 35986175 | ... AW39: =AW34-AW37 -> 21993560
H40: % | J40: =J39/J5 -> -0.050286223 | K40: =K39/K5 -> 0.027987143 | L40: =L39/L5 -> 0.010245116 | M40: =M39/M5 -> 0.1501345 | N40: =N39/N5 -> 0.059496249 | O40: =O39/O5 -> -0.089146647 | P40: =P39/P5 -> 0.0035429546 | Q40: =Q39/Q5 -> 0.12843384 | ... U40: =U39/U5 -> 0.15422368 | W40: % | X40: =X39/X5 -> -0.14298317 | Y40: =Y39/Y5 -> 0.14230267 | Z40: =Z39/Z5 -> 0.12876839 | AA40: =AA39/AA5 -> 0.23096326 | AB40: =AB39/AB5 -> 0.16068311 | AC40: =AC39/AC5 -> 0.014861045 | AD40: =AD39/AD5 -> 0.05926502 | AE40: =AE39/AE5 -> 0.16861932 | ... AI40: =AI39/AI5 -> 0.12961846 | AK40: % | AL40: =AL39/AL5 -> 0.079031107 | AM40: =AM39/AM5 -> 0.10553293 | AN40: =AN39/AN5 -> 0.090645229 | AO40: =AO39/AO5 -> 0.20305958 | AP40: =AP39/AP5 -> 0.12575142 | AQ40: =AQ39/AQ5 -> -0.034652851 | AR40: =AR39/AR5 -> 0.014191522 | AS40: =AS39/AS5 -> 0.13448125 | ... AW40: =AW39/AW5 -> 0.091580306
B41: WACC Año 1 | C41: ='Cash Flow'!H35 -> 0.22808944
G42: Impuestos | J42: =IF(J39>0,J39*$C$30,0) -> 0 | K42: =IF(K39>0,K39*$C$30,0) -> 229453.61 | L42: =IF(L39>0,L39*$C$30,0) -> 81013.015 | M42: =IF(M39>0,M39*$C$30,0) -> 1757146.7 | N42: =IF(N39>0,N39*$C$30,0) -> 556235.77 | O42: =IF(O39>0,O39*$C$30,0) -> 0 | P42: =IF(P39>0,P39*$C$30,0) -> 27645.085 | Q42: =IF(Q39>0,Q39*$C$30,0) -> 1417677.2 | ... U42: =IF(U39>0,U39*$C$30,0) -> 2037075.8 | X42: =IF(X39>0,X39*$C$30,0) -> 0 | Y42: =IF(Y39>0,Y39*$C$30,0) -> 1944456 | Z42: =IF(Z39>0,Z39*$C$30,0) -> 1697055 | AA42: =IF(AA39>0,AA39*$C$30,0) -> 4158695 | AB42: =IF(AB39>0,AB39*$C$30,0) -> 2311139.6 | AC42: =IF(AC39>0,AC39*$C$30,0) -> 150798.78 | AD42: =IF(AD39>0,AD39*$C$30,0) -> 660621.55 | AE42: =IF(AE39>0,AE39*$C$30,0) -> 2481669.6 | ... AI42: =IF(AI39>0,AI39*$C$30,0) -> 1712075.8 | AL42: =IF(AL39>0,AL39*$C$30,0) -> 921356.5 | AM42: =IF(AM39>0,AM39*$C$30,0) -> 1310932.8 | AN42: =IF(AN39>0,AN39*$C$30,0) -> 1086022.8 | AO42: =IF(AO39>0,AO39*$C$30,0) -> 3323877.2 | AP42: =IF(AP39>0,AP39*$C$30,0) -> 1644281.5 | AQ42: =IF(AQ39>0,AQ39*$C$30,0) -> 0 | AR42: =IF(AR39>0,AR39*$C$30,0) -> 143810.5 | AS42: =IF(AS39>0,AS39*$C$30,0) -> 1799308.8 | ... AW42: =IF(AW39>0,AW39*$C$30,0) -> 1099678
B43: Payback (meses) | C43: =_xlfn.XLOOKUP("PAYBACK",I94:AW94,I91:AW91,"+ de 36 meses") -> + de 36 meses
...

Sheet Cash Flow
E1: 0 | F1: 1 | G1: 2 | H1: 3 | I1: 4 | J1: 5 | K1: 6 | L1: 7 | M1: 8 | N1: 9 | O1: 10
B3: TC | E3: 1420 | F3: 1420 | G3: 1420 | H3: 1420 | I3: 1420 | J3: 1420 | K3: 1420 | L3: 1420 | M3: 1420 | N3: 1420 | O3: 1420
B4: Evolución esperada del riesgo país | E4: 0.05 | F4: 0.03 | G4: 0.01 | H4: 0.01 | I4: 0.01 | J4: 0.01 | K4: 0.01 | L4: 0.01 | M4: 0.01 | N4: 0.01 | O4: 0.01 | P4: 0.01
B5: Kwacc | E5: =+(1-H26)*D26+H26*D24*(1-H27) -> 0.22808944 | F5: =$D$30+($H$25*($D$33+F4+$D$36+$D$37)) -> 0.17855344 | G5: =$D$30+($H$25*($D$33+G4+$D$36+$D$37)) -> 0.16309744 | H5: =$D$30+($H$25*($D$33+H4+$D$36+$D$37)) -> 0.16309744 | I5: =$D$30+($H$25*($D$33+I4+$D$36+$D$37)) -> 0.16309744 | J5: =$D$30+($H$25*($D$33+J4+$D$36+$D$37)) -> 0.16309744 | K5: =$D$30+($H$25*($D$33+K4+$D$36+$D$37)) -> 0.16309744 | L5: =$D$30+($H$25*($D$33+L4+$D$36+$D$37)) -> 0.16309744 | M5: =$D$30+($H$25*($D$33+M4+$D$36+$D$37)) -> 0.16309744 | ... P5: =$D$30+($H$25*($D$33+P4+$D$36+$D$37)) -> 0.16309744
B6: Cash Flow | D6: Unidad | E6: Año 0 | F6: Año 1 | G6: Año 2 | H6: Año 3 | I6: Año 4 | J6: Año 5 | K6: Año 6 | L6: Año 7 | M6: Año 8 | N6: Año 9 | O6: Año 10 | P6: Año 11
B7: NOPAT | D7: USD | F7: =SUM('EERR Mensual'!J62:U62) -> 128548.24 | G7: =SUM('EERR Mensual'!X62:AI62) -> 256260.51 | H7: =G7 -> 256260.51 | I7: =H7 -> 256260.51 | J7: =I7 -> 256260.51 | K7: =J7 -> 256260.51 | L7: =K7 -> 256260.51 | M7: =L7 -> 256260.51 | N7: =M7 -> 256260.51 | O7: =N7 -> 256260.51 | P7: =O7*(1+S10) -> 263948.32 | R7: Ronic | S7: 0.1
B8: FFL | D8: USD | E8: ='EERR Mensual'!I74 -> -431000 | F8: ='EERR Mensual'!U83 -> 106633.8 | G8: ='EERR Mensual'!AI83 -> 188855.54 | H8: =G8 -> 188855.54 | I8: =H8 -> 188855.54 | J8: =I8 -> 188855.54 | K8: =J8 -> 188855.54 | L8: =K8 -> 188855.54 | M8: =L8 -> 188855.54 | N8: =M8 -> 188855.54 | O8: =N8 -> 188855.54 | P8: =P7*(1-S8) -> 184763.82 | R8: TRI | S8: =S10/S7 -> 0.3
B9: Valor Residual FFL | D9: USD | O9: =IF(F14="Si",P8/(P5-S10),0) -> 0
B10: FFL + Valor Residual | D10: USD | E10: =E8+E9 -> -431000 | F10: =F8+F9 -> 106633.8 | G10: =G8+G9 -> 188855.54 | H10: =H8+H9 -> 188855.54 | I10: =I8+I9 -> 188855.54 | J10: =J8+J9 -> 188855.54 | K10: =K8+K9 -> 188855.54 | L10: =L8+L9 -> 188855.54 | ... O10: =O8+O9 -> 188855.54 | R10: g | S10: =[1]DASHBOARD!C8 -> 0.03
B11: Factor de descuento | D11: USD | E11: =1/(1+$E$5)^0 -> 1 | F11: =1/(1+F5)^F1 -> 0.8484978 | G11: =1/(1+G5)^G1 -> 0.73920994 | H11: =1/(1+H5)^H1 -> 0.63555289 | I11: =1/(1+I5)^I1 -> 0.54643134 | J11: =1/(1+J5)^J1 -> 0.46980702 | K11: =1/(1+K5)^K1 -> 0.40392748 | L11: =1/(1+L5)^L1 -> 0.34728602 | M11: =1/(1+M5)^M1 -> 0.29858721 | ... O11: =1/(1+O5)^O1 -> 0.22071863
B12: Valor presente de FFL + VR FFL | D12: USD | E12: =E10*E11 -> -431000 | F12: =F10*F11 -> 90478.542 | G12: =G10*G11 -> 139603.89 | H12: =H10*H11 -> 120027.68 | I12: =I10*I11 -> 103196.58 | J12: =J10*J11 -> 88725.657 | K12: =K10*K11 -> 76283.942 | L12: =L10*L11 -> 65586.888 | ... O12: =O10*O11 -> 41683.937
B14: VAN | C14: =SUM(E12:O12) -> 399459.45 | E14: VALOR RESIDUAL | F14: No
B16: TIR | C16: =IRR(E10:O10,0.1) -> 0.36776345
B20: VALUACIÓN POR WACC
B22: TASAS DE DESCUENTO
B24: Kd | D24: =+D30+D34 -> 0.0479 | G24: Beta desapalancada | H24: =D31*(1-D32) -> 0.7728
B25: Ku | D25: =+D30+D33*H24+D35 -> 0.12808944 | G25: Beta re-apalancada | H25: =+H24*(1+H26/(1-H26)) -> 0.7728
B26: Ke | D26: =+D30+(D33*H25)+D35+D36+D37 -> 0.22808944 | G26: D/V | H26: 0
B27: Kwacc | D27: =+(1-H26)*D26+H26*D24*(1-H27) -> 0.22808944 | G27: t | H27: 0.35
B29: INPUTS PARA TASA DESCUENTO
B30: Bonos de tesoro USA - 10Y | D30: 0.0454 | G30: Risk Free Rate | H30: =D30 -> 0.0454
B31: Beta aplancada de la industria | D31: 0.92 | E31: Damodaran - Restaurant Dining | G31: Bu | H31: =H24 -> 0.7728
B32: D/V de la industria | D32: 0.16 | G32: ERP | H32: =D33 -> 0.0423
B33: Prima de riesgo mercado | D33: 0.0423 | E33: Damodaran | G33: Riesgo País | H33: =D35 -> 0.05
B34: Prima de riesgo no pago de la deuda | D34: 0.0025 | G34: Ke | H34: =D26 -> 0.22808944
B35: Prima de riesgo país | D35: 0.05 | E35: JPMORGAN EMBI+ | G35: Wacc | H35: =H34 -> 0.22808944
B36: Prima por Iliquidez | D36: 0.05
B37: Prima por empresa chica | D37: 0.05

Sheet ITEMS
B2: ITEM | C2: Nota Diego | D2: Inputs Gastón
B3: Ver el Ramp Up de ventas | C3: Puse un modificador para llegar a los clientes esperados. Estaba puesto como que arranca el primer mes al palo. Lo más probable es que no arranquemos el 1 del mes, o que tarde unos meses en venir la clientela que queremos.
B4: Ver si las ventas crecen en año 2 y subsiguientes | C4: Puse ventas constantes, pero asumo que el segundo año si todo va bien hay lugar para crecer en ventas.
B5: Ver días de caja necesaria
B6: Ver días de clientes | C6: Hay que ver bien cuándo entra la guita. Si hay un porcentaje de comisión de 11% en el EERR, eso es porque reciben la guita en el momento y ahí están las comisiones por ello?
B7: Ver días de proveedores | C7: Hay que ver a cuántos días se les puede pagar a los proveedores, particularmente a los de materia prima. Los empleados y costos fijos como alquiiler asumimos son a mes vencido.
B8: Ver comisiones / Impuestos | C8: En qué momento se pagan?
B9: Ver impueso a las ganancias | C9: Puse 10%, cuánto puede ser? | D9: Es 5
B10: Ver Ticket Promedio | C10: Este item es bastante crítico. Ver análisis de sensibilidad.
B11: Ver Prevision para despidos | C11: Hasta qué monto guardamos? Esto debiera ir a una cuenta remunerada en dólares. | D11: Topear en 10.000 usd
B12: Ver monto servicios públicos | C12: Está fijo en 6.800.000, debiera ser variable con actividad. Ver cómo calzan los pagos porque impacta en los primeros meses en la caja necesaria para arrancar.
B13: Ver estructura de bonos | C13: No hay nada puesto, cómo lo pensaron esto?
B14: Ver items como inversión, bazar, etc | C14: Cuánto hay que guardar de esto?
B15: Ver RRHH | C15: Entender cómo funciona la cantidad de gente y si hay aumento temporal durante temporada alta. Puse 60 millones para redondear. REVISAR! | D15: Ya lo vimos
B16: El marketing debiera ir como costo fijo. Si vendés CERO, entonces invertís cero en MKT? | C16: Quién maneja esto? Habría que invertir más al inicio para darse a conocer.
B17: VER CUSTOMER JOURNEY + FUNNEL | C17: Tienen hecho esto para el CDB?
B18: Chequear CAPEX final
B19: Revisar cada item y linea del EERR y el Cashflow
B20: Prevision de aguinaldos | C20: Debiera ir a una cuenta money market o similar.
B21: Prevision de impuestos | C21: Debiera ir a una cuenta money market o similar. En pesos o en usd? Si el dólar baja y está en usd cagamos, viceversa ganamos.
B22: Anticipos de ganancias | C22: Esto no está contemplado
B23: IVA | C23: Esto tampoco está contemplado. Entender bien el manejo de esto y como impacta.
B24: TIPO de cambio | C24: Lo dejé constante. Lo más probable es que baje, mejorando los ingresos en dólares. Por simplicidad lo dejaría fijo.
